В ходе работы той или иной части программы может возникнуть ситуация, вызывающая некоторую ошибку выполнения. Например деление на ноль, отсутствие файла на диске и т.д. Подобного рода ошибки можно предусмотреть заранее, организовав их обработку внутри блока, где ошибка может возникнуть сразу при написании кода.
```
double smth(char* name) {
	ifstream f(name);
	int count = 0, sum = 0, a;
	while (!f.eof()) {
		f >> a;
		sum += a;
		count++;
	}
	f.close;
	// possible division by zero
	return ((double)sum) / n;
}
```
// Note: в лабах никаких лишних выводов в консоль
Для того, чтобы обработать исключения, в языке С создан механизм обработки исключений с помощью трёх служебных слов: `try`, `catch`, `throw`. 
```try { block }``` позволяет выделить контроллируемый блок, в котором может произойти исключение
`catch(ExceptionType& e) { block }` - т.н. обработчик исключения, ставящийся после `try`. В скобках указывается тип исключения, операторы, действия, которые нужно выполнить при возникновении исключения
`throw` - когда выполняется такой оператор, то с помощью выражения, стоящего после `throw`, формируется специальный объект, называемый исключением. Тип объекта определяется типом выражения после `throw`. Как только выполнился оператор `throw`, управление передаётся в первый блок `catch`, стоящий после `try`.
```
float divideNumbers(int a, int b) {  
    if (b == 0) {  
        throw (std::overflow_error("Division by zero"));  
    }  
    if (a == 0) {  
        throw (std::domain_error("Divided zero by number"));  
    }  
    return a / b;  
}  
  
int main() {  
    cout << divideNumbers(3, 2) << endl;  
    try {  
        cout << divideNumbers(3, 0) << endl;  
    }  
    catch (std::overflow_error &e) {  
        cout << "Exception: " << e.what() << endl;  
    }  
}
```
Один и тот же блок может возвращать несколько исключений, при этом выражения, выбрасывающие исключение, могут быть разных типов. В этом случае после `try` может быть несколько блоков `catch`, каждый для своего типа.
В C++ существует иерархия классов исключений:
![[Assets/std-exception-types.png]]
Класс `exception`  является базовым классом родительским классом для всех классов исключений. У него имеется метод `exception.what()`, который возвращает информацию о типе исключения.
`runtime_error` - общий тип исключений, возникающий в процессе выполнения программы. От него наследуются три класса - `overflow_error`, `range_error`, `underflow_error`.